Error while calling `get_updates` one more time to mark all fetched updates as read: %s. Suppressing error to ensure graceful shutdown. When polling for updates is restarted, updates may be fetched again. Please adjust timeouts via `ApplicationBuilder` or the parameter `get_updates_request` of `Bot`.
Traceback (most recent call last):
  File "/Users/mac/Library/Python/3.9/lib/python/site-packages/httpx/_transports/default.py", line 72, in map_httpcore_exceptions
    yield
  File "/Users/mac/Library/Python/3.9/lib/python/site-packages/httpx/_transports/default.py", line 377, in handle_async_request
    resp = await self._pool.handle_async_request(req)
  File "/Users/mac/Library/Python/3.9/lib/python/site-packages/httpcore/_async/connection_pool.py", line 216, in handle_async_request
    raise exc from None
  File "/Users/mac/Library/Python/3.9/lib/python/site-packages/httpcore/_async/connection_pool.py", line 196, in handle_async_request
    response = await connection.handle_async_request(
  File "/Users/mac/Library/Python/3.9/lib/python/site-packages/httpcore/_async/connection.py", line 99, in handle_async_request
    raise exc
  File "/Users/mac/Library/Python/3.9/lib/python/site-packages/httpcore/_async/connection.py", line 76, in handle_async_request
    stream = await self._connect(request)
  File "/Users/mac/Library/Python/3.9/lib/python/site-packages/httpcore/_async/connection.py", line 122, in _connect
    stream = await self._network_backend.connect_tcp(**kwargs)
  File "/Users/mac/Library/Python/3.9/lib/python/site-packages/httpcore/_backends/auto.py", line 30, in connect_tcp
    return await self._backend.connect_tcp(
  File "/Users/mac/Library/Python/3.9/lib/python/site-packages/httpcore/_backends/anyio.py", line 124, in connect_tcp
    stream._raw_socket.setsockopt(*option)  # type: ignore[attr-defined] # pragma: no cover
  File "/Applications/Xcode.app/Contents/Developer/Library/Frameworks/Python3.framework/Versions/3.9/lib/python3.9/contextlib.py", line 135, in __exit__
    self.gen.throw(type, value, traceback)
  File "/Users/mac/Library/Python/3.9/lib/python/site-packages/httpcore/_exceptions.py", line 14, in map_exceptions
    raise to_exc(exc) from exc
httpcore.ConnectError: [Errno 8] nodename nor servname provided, or not known

The above exception was the direct cause of the following exception:

Traceback (most recent call last):
  File "/Users/mac/Library/Python/3.9/lib/python/site-packages/telegram/request/_httpxrequest.py", line 292, in do_request
    res = await self._client.request(
  File "/Users/mac/Library/Python/3.9/lib/python/site-packages/httpx/_client.py", line 1585, in request
    return await self.send(request, auth=auth, follow_redirects=follow_redirects)
  File "/Users/mac/Library/Python/3.9/lib/python/site-packages/httpx/_client.py", line 1674, in send
    response = await self._send_handling_auth(
  File "/Users/mac/Library/Python/3.9/lib/python/site-packages/httpx/_client.py", line 1702, in _send_handling_auth
    response = await self._send_handling_redirects(
  File "/Users/mac/Library/Python/3.9/lib/python/site-packages/httpx/_client.py", line 1739, in _send_handling_redirects
    response = await self._send_single_request(request)
  File "/Users/mac/Library/Python/3.9/lib/python/site-packages/httpx/_client.py", line 1776, in _send_single_request
    response = await transport.handle_async_request(request)
  File "/Users/mac/Library/Python/3.9/lib/python/site-packages/httpx/_transports/default.py", line 377, in handle_async_request
    resp = await self._pool.handle_async_request(req)
  File "/Applications/Xcode.app/Contents/Developer/Library/Frameworks/Python3.framework/Versions/3.9/lib/python3.9/contextlib.py", line 135, in __exit__
    self.gen.throw(type, value, traceback)
  File "/Users/mac/Library/Python/3.9/lib/python/site-packages/httpx/_transports/default.py", line 89, in map_httpcore_exceptions
    raise mapped_exc(message) from exc
httpx.ConnectError: [Errno 8] nodename nor servname provided, or not known

The above exception was the direct cause of the following exception:

Traceback (most recent call last):
  File "/Users/mac/Library/Python/3.9/lib/python/site-packages/telegram/ext/_updater.py", line 438, in _get_updates_cleanup
    await self.bot.get_updates(
  File "/Users/mac/Library/Python/3.9/lib/python/site-packages/telegram/ext/_extbot.py", line 649, in get_updates
    updates = await super().get_updates(
  File "/Users/mac/Library/Python/3.9/lib/python/site-packages/telegram/_bot.py", line 4366, in get_updates
    await self._post(
  File "/Users/mac/Library/Python/3.9/lib/python/site-packages/telegram/_bot.py", line 623, in _post
    return await self._do_post(
  File "/Users/mac/Library/Python/3.9/lib/python/site-packages/telegram/ext/_extbot.py", line 355, in _do_post
    return await super()._do_post(
  File "/Users/mac/Library/Python/3.9/lib/python/site-packages/telegram/_bot.py", line 652, in _do_post
    result = await request.post(
  File "/Users/mac/Library/Python/3.9/lib/python/site-packages/telegram/request/_baserequest.py", line 201, in post
    result = await self._request_wrapper(
  File "/Users/mac/Library/Python/3.9/lib/python/site-packages/telegram/request/_baserequest.py", line 333, in _request_wrapper
    code, payload = await self.do_request(
  File "/Users/mac/Library/Python/3.9/lib/python/site-packages/telegram/request/_httpxrequest.py", line 316, in do_request
    raise NetworkError(f"httpx.{err.__class__.__name__}: {err}") from err
telegram.error.NetworkError: httpx.ConnectError: [Errno 8] nodename nor servname provided, or not known
